Workbook

Sheet Order Page
A1: Week 1
A2: Inventory Order List | E2: =IF('Inventory '!B2="","",'Inventory '!B2) -> 46216
A3: ='Inventory '!A50 -> #NAME?
A5: Utensil Order List | E5: =IF('Untensil PG1'!B2="","",'Untensil PG1'!B2) -> 46213
A6: ='Untensil PG1'!A41 -> #NAME?
A7: ='Utensil PG2'!A46 -> #NAME?
A9: Week 2
A10: Inventory Order List | E10: =IF('Inventory '!G2="","",'Inventory '!G2)
A11: ='Inventory '!A51
A13: Utensil Order List | E13: =IF('Untensil PG1'!E2="","",'Untensil PG1'!E2)
A14: ='Untensil PG1'!A42
A15: ='Utensil PG2'!A47 -> 0
A17: Week 3
A18: Inventory Order List | E18: =IF('Inventory '!L2="","",'Inventory '!L2)
A19: ='Inventory '!A52
A21: Utensil Order List | E21: =IF('Untensil PG1'!H2="","",'Untensil PG1'!H2)
A22: ='Untensil PG1'!A43
A23: ='Utensil PG2'!A48
A25: Week 4
A26: Inventory Order List | E26: =IF('Inventory '!Q2="","",'Inventory '!Q2)
A27: ='Inventory '!A53
A29: Utensil Order List | E29: =IF('Untensil PG1'!K2="","",'Untensil PG1'!K2)
A30: ='Untensil PG1'!A44
A31: ='Utensil PG2'!A49
A33: Week 5
A34: Inventory Order List | E34: =IF('Inventory '!V2="","",'Inventory '!V2)
A35: ='Inventory '!A54
A37: Utensil Order List | E37: =IF('Untensil PG1'!N2="","",'Untensil PG1'!N2)
A38: ='Untensil PG1'!A45
A39: ='Utensil PG2'!A50
A43: Stationary Stock (MONTLY) | F43: =IF('Stationary '!B2="","",'Stationary '!B2)
A44: ='Stationary '!A44

Sheet Inventory 
A1: Inventory listing 2026
A2: ITEM | B2: 46216
B3: Quantity and Unit | F3: Status | G3: Quantity and Unit | K3: Status | L3: Quantity and Unit | P3: Status | Q3: Quantity and Unit | U3: Status | V3: Quantity and Unit | Z3: Status | AA3: MIN
A4: Mayonaise (TELLY) | B4: 4 | D4: Pack | F4: =IF(B4<=$AA4,"Order","") -> Order | I4: Pack | K4: =IF(G4<=$AA4,"Order","") -> Order | N4: Pack | P4: =IF(L4<=$AA4,"Order","") -> Order | S4: Pack | U4: =IF(Q4<=$AA4,"Order","") -> Order | X4: Pack | Z4: =IF(V4<=$AA4,"Order","") -> Order | AA4: 4 | AD4: =IF(F4="Order",A4,"") -> Mayonaise (TELLY) | AE4: =IF(K4="Order",A4,"") -> Mayonaise (TELLY) | AF4: =IF(P4="Order",A4,"") -> Mayonaise (TELLY) | AG4: =IF(U4="Order",A4,"") -> Mayonaise (TELLY) | AH4: =IF(Z4="Order",A4,"") -> Mayonaise (TELLY)
A5: Pineapple Slice (AYAM BRAND) | B5: 2.5 | D5: Ctn | F5: =IF(B5<=$AA5,"Order","") -> Order | I5: Ctn | K5: =IF(G5<=$AA5,"Order","") -> Order | N5: Ctn | P5: =IF(L5<=$AA5,"Order","") -> Order | S5: Ctn | U5: =IF(Q5<=$AA5,"Order","") -> Order | X5: Ctn | Z5: =IF(V5<=$AA5,"Order","") -> Order | AA5: 12 | AD5: =IF(F5="Order",A5,"") -> Pineapple Slice (AYAM BRAND) | AE5: =IF(K5="Order",A5,"") -> Pineapple Slice (AYAM BRAND) | AF5: =IF(P5="Order",A5,"") -> Pineapple Slice (AYAM BRAND) | AG5: =IF(U5="Order",A5,"") -> Pineapple Slice (AYAM BRAND) | AH5: =IF(Z5="Order",A5,"") -> Pineapple Slice (AYAM BRAND)
A6: Magarine (COOKING BRAND) | B6: 1.5 | D6: Ctn | F6: =IF(B6<=$AA6,"Order","") | I6: Ctn | K6: =IF(G6<=$AA6,"Order","") -> Order | N6: Ctn | P6: =IF(L6<=$AA6,"Order","") -> Order | S6: Ctn | U6: =IF(Q6<=$AA6,"Order","") -> Order | X6: Ctn | Z6: =IF(V6<=$AA6,"Order","") -> Order | AA6: 1 | AD6: =IF(F6="Order",A6,"") | AE6: =IF(K6="Order",A6,"") -> Magarine (COOKING BRAND) | AF6: =IF(P6="Order",A6,"") -> Magarine (COOKING BRAND) | AG6: =IF(U6="Order",A6,"") -> Magarine (COOKING BRAND) | AH6: =IF(Z6="Order",A6,"") -> Magarine (COOKING BRAND)
A7: Fructose Syrup ( 18CTEA) | B7: 1.2 | D7: Bottle | F7: =IF(B7<=$AA7,"Order","") | I7: Bottle | K7: =IF(G7<=$AA7,"Order","") -> Order | N7: Bottle | P7: =IF(L7<=$AA7,"Order","") -> Order | S7: Bottle | U7: =IF(Q7<=$AA7,"Order","") -> Order | X7: Bottle | Z7: =IF(V7<=$AA7,"Order","") -> Order | AA7: 0.5 | AD7: =IF(F7="Order",A7,"") | AE7: =IF(K7="Order",A7,"") -> Fructose Syrup ( 18CTEA) | AF7: =IF(P7="Order",A7,"") -> Fructose Syrup ( 18CTEA) | AG7: =IF(U7="Order",A7,"") -> Fructose Syrup ( 18CTEA) | AH7: =IF(Z7="Order",A7,"") -> Fructose Syrup ( 18CTEA)
A8: Cooking Oil | B8: 16.7 | D8: Bottle | F8: =IF(B8<=$AA8,"Order","") | I8: Bottle | K8: =IF(G8<=$AA8,"Order","") -> Order | N8: Bottle | P8: =IF(L8<=$AA8,"Order","") -> Order | S8: Bottle | U8: =IF(Q8<=$AA8,"Order","") -> Order | X8: Bottle | Z8: =IF(V8<=$AA8,"Order","") -> Order | AA8: 3 | AD8: =IF(F8="Order",A8,"") | AE8: =IF(K8="Order",A8,"") -> Cooking Oil | AF8: =IF(P8="Order",A8,"") -> Cooking Oil | AG8: =IF(U8="Order",A8,"") -> Cooking Oil | AH8: =IF(Z8="Order",A8,"") -> Cooking Oil
A9: Tomato Sauce (MAGGI) | B9: 0.2 | D9: Pack | F9: =IF(B9<=$AA9,"Order","") | I9: Pack | K9: =IF(G9<=$AA9,"Order","") -> Order | N9: Pack | P9: =IF(L9<=$AA9,"Order","") -> Order | S9: Pack | U9: =IF(Q9<=$AA9,"Order","") -> Order | X9: Pack | Z9: =IF(V9<=$AA9,"Order","") -> Order | AA9: 0 | AD9: =IF(F9="Order",A9,"") | AE9: =IF(K9="Order",A9,"") -> Tomato Sauce (MAGGI) | AF9: =IF(P9="Order",A9,"") -> Tomato Sauce (MAGGI) | AG9: =IF(U9="Order",A9,"") -> Tomato Sauce (MAGGI) | AH9: =IF(Z9="Order",A9,"") -> Tomato Sauce (MAGGI)
A10: Chilli Sauce (MAGGI) | B10: 1.5 | D10: Pack | F10: =IF(B10<=$AA10,"Order","") | I10: Pack | K10: =IF(G10<=$AA10,"Order","") -> Order | N10: Pack | P10: =IF(L10<=$AA10,"Order","") -> Order | S10: Pack | U10: =IF(Q10<=$AA10,"Order","") -> Order | X10: Pack | Z10: =IF(V10<=$AA10,"Order","") -> Order | AA10: 0 | AD10: =IF(F10="Order",A10,"") | AE10: =IF(K10="Order",A10,"") -> Chilli Sauce (MAGGI) | AF10: =IF(P10="Order",A10,"") -> Chilli Sauce (MAGGI) | AG10: =IF(U10="Order",A10,"") -> Chilli Sauce (MAGGI) | AH10: =IF(Z10="Order",A10,"") -> Chilli Sauce (MAGGI)
A11: Chocolate (DUTCH LADY) | B11: 2 | C11: Ctn | D11: 16 | E11: Box | F11: =IF(((B11*6)+D11)<=$AA11,"Order","") | H11: Ctn | J11: Box | K11: =IF(((G11*6)+I11)<=$AA11,"Order","") -> Order | M11: Ctn | O11: Box | P11: =IF(((L11*6)+N11)<=$AA11,"Order","") -> Order | R11: Ctn | T11: Box | U11: =IF(((Q11*6)+S11)<=$AA11,"Order","") -> Order | W11: Ctn | Y11: Box | Z11: =IF(((V11*6)+X11)<=$AA11,"Order","") -> Order | AA11: 6 | AD11: =IF(F11="Order",A11,"") | AE11: =IF(K11="Order",A11,"") -> Chocolate (DUTCH LADY) | AF11: =IF(P11="Order",A11,"") -> Chocolate (DUTCH LADY) | AG11: =IF(U11="Order",A11,"") -> Chocolate (DUTCH LADY) | AH11: =IF(Z11="Order",A11,"") -> Chocolate (DUTCH LADY)
A12: Hash Brown (SIMPLOT) | B12: 5 | D12: Box | F12: =IF(B12<=$AA12,"Order","") -> Order | I12: Box | K12: =IF(G12<=$AA12,"Order","") -> Order | N12: Box | P12: =IF(L12<=$AA12,"Order","") -> Order | S12: Box | U12: =IF(Q12<=$AA12,"Order","") -> Order | X12: Box | Z12: =IF(V12<=$AA12,"Order","") -> Order | AA12: 5 | AD12: =IF(F12="Order",A12,"") -> Hash Brown (SIMPLOT) | AE12: =IF(K12="Order",A12,"") -> Hash Brown (SIMPLOT) | AF12: =IF(P12="Order",A12,"") -> Hash Brown (SIMPLOT) | AG12: =IF(U12="Order",A12,"") -> Hash Brown (SIMPLOT) | AH12: =IF(Z12="Order",A12,"") -> Hash Brown (SIMPLOT)
A13: Mineral Water | B13: 3 | C13: Ctn | D13: 1 | E13: Btl | F13: =IF(((B13*24)+D13)<=$AA13,"Order","") | H13: Ctn | J13: Btl | K13: =IF(((G13*24)+I13)<=$AA13,"Order","") -> Order | M13: Ctn | O13: Btl | P13: =IF(((L13*24)+N13)<=$AA13,"Order","") -> Order | R13: Ctn | T13: Btl | U13: =IF(((Q13*24)+S13)<=$AA13,"Order","") -> Order | W13: Ctn | Y13: Btl | Z13: =IF(((V13*24)+X13)<=$AA13,"Order","") -> Order | AA13: 48 | AD13: =IF(F13="Order",A13,"") | AE13: =IF(K13="Order",A13,"") -> Mineral Water | AF13: =IF(P13="Order",A13,"") -> Mineral Water | AG13: =IF(U13="Order",A13,"") -> Mineral Water | AH13: =IF(Z13="Order",A13,"") -> Mineral Water
A14: Coca-Cola | B14: 1 | C14: Ctn | D14: 21 | E14: Btl | F14: =IF(((B14*24)+D14)<=$AA14,"Order","") -> Order | H14: Ctn | J14: Btl | K14: =IF(((G14*24)+I14)<=$AA14,"Order","") -> Order | M14: Ctn | O14: Btl | P14: =IF(((L14*24)+N14)<=$AA14,"Order","") -> Order | R14: Ctn | T14: Btl | U14: =IF(((Q14*24)+S14)<=$AA14,"Order","") -> Order | W14: Ctn | Y14: Btl | Z14: =IF(((V14*24)+X14)<=$AA14,"Order","") -> Order | AA14: 48 | AD14: =IF(F14="Order",A14,"") -> Coca-Cola | AE14: =IF(K14="Order",A14,"") -> Coca-Cola | AF14: =IF(P14="Order",A14,"") -> Coca-Cola | AG14: =IF(U14="Order",A14,"") -> Coca-Cola | AH14: =IF(Z14="Order",A14,"") -> Coca-Cola
A15: 100 Plus | B15: 1 | C15: Ctn | D15: 9 | E15: Btl | F15: =IF(((B15*24)+D15)<=$AA15,"Order","") -> Order | H15: Ctn | J15: Btl | K15: =IF(((G15*24)+I15)<=$AA15,"Order","") -> Order | M15: Ctn | O15: Btl | P15: =IF(((L15*24)+N15)<=$AA15,"Order","") -> Order | R15: Ctn | T15: Btl | U15: =IF(((Q15*24)+S15)<=$AA15,"Order","") -> Order | W15: Ctn | Y15: Btl | Z15: =IF(((V15*24)+X15)<=$AA15,"Order","") -> Order | AA15: 48 | AD15: =IF(F15="Order",A15,"") -> 100 Plus | AE15: =IF(K15="Order",A15,"") -> 100 Plus | AF15: =IF(P15="Order",A15,"") -> 100 Plus | AG15: =IF(U15="Order",A15,"") -> 100 Plus | AH15: =IF(Z15="Order",A15,"") -> 100 Plus
A16: Sencha Japanese Green Tea | B16: 40 | D16: Bottles | F16: =IF(B16<=$AA16,"Order","") -> Order | I16: Bottles | K16: =IF(G16<=$AA16,"Order","") -> Order | N16: Bottles | P16: =IF(L16<=$AA16,"Order","") -> Order | S16: Bottles | U16: =IF(Q16<=$AA16,"Order","") -> Order | X16: Bottles | Z16: =IF(V16<=$AA16,"Order","") -> Order | AA16: 40 | AD16: =IF(F16="Order",A16,"") -> Sencha Japanese Green Tea | AE16: =IF(K16="Order",A16,"") -> Sencha Japanese Green Tea | AF16: =IF(P16="Order",A16,"") -> Sencha Japanese Green Tea | AG16: =IF(U16="Order",A16,"") -> Sencha Japanese Green Tea | AH16: =IF(Z16="Order",A16,"") -> Sencha Japanese Green Tea
A17: Salt | B17: 0.2 | D17: Pack | F17: =IF(B17<=$AA17,"Order","") | I17: Pack | K17: =IF(G17<=$AA17,"Order","") -> Order | N17: Pack | P17: =IF(L17<=$AA17,"Order","") -> Order | S17: Pack | U17: =IF(Q17<=$AA17,"Order","") -> Order | X17: Pack | Z17: =IF(V17<=$AA17,"Order","") -> Order | AA17: 0 | AD17: =IF(F17="Order",A17,"") | AE17: =IF(K17="Order",A17,"") -> Salt | AF17: =IF(P17="Order",A17,"") -> Salt | AG17: =IF(U17="Order",A17,"") -> Salt | AH17: =IF(Z17="Order",A17,"") -> Salt
A18: Pepper | B18: 1 | D18: Pack | F18: =IF(B18<=$AA18,"Order","") | I18: Pack | K18: =IF(G18<=$AA18,"Order","") -> Order | N18: Pack | P18: =IF(L18<=$AA18,"Order","") -> Order | S18: Pack | U18: =IF(Q18<=$AA18,"Order","") -> Order | X18: Pack | Z18: =IF(V18<=$AA18,"Order","") -> Order | AA18: 0.5 | AD18: =IF(F18="Order",A18,"") | AE18: =IF(K18="Order",A18,"") -> Pepper | AF18: =IF(P18="Order",A18,"") -> Pepper | AG18: =IF(U18="Order",A18,"") -> Pepper | AH18: =IF(Z18="Order",A18,"") -> Pepper
A19: Paprika | B19: 0 | D19: Bottles | F19: =IF(B19<=$AA19,"Order","") -> Order | I19: Bottles | K19: =IF(G19<=$AA19,"Order","") -> Order | N19: Bottles | P19: =IF(L19<=$AA19,"Order","") -> Order | S19: Bottles | U19: =IF(Q19<=$AA19,"Order","") -> Order | X19: Bottles | Z19: =IF(V19<=$AA19,"Order","") -> Order | AA19: 0.5 | AD19: =IF(F19="Order",A19,"") -> Paprika | AE19: =IF(K19="Order",A19,"") -> Paprika | AF19: =IF(P19="Order",A19,"") -> Paprika | AG19: =IF(U19="Order",A19,"") -> Paprika | AH19: =IF(Z19="Order",A19,"") -> Paprika
A20: Chilli Powder | B20: 0 | D20: Pack | F20: =IF(B20<=$AA20,"Order","") -> Order | I20: Pack | K20: =IF(G20<=$AA20,"Order","") -> Order | N20: Pack | P20: =IF(L20<=$AA20,"Order","") -> Order | S20: Pack | U20: =IF(Q20<=$AA20,"Order","") -> Order | X20: Pack | Z20: =IF(V20<=$AA20,"Order","") -> Order | AA20: 0.5 | AD20: =IF(F20="Order",A20,"") -> Chilli Powder | AE20: =IF(K20="Order",A20,"") -> Chilli Powder | AF20: =IF(P20="Order",A20,"") -> Chilli Powder | AG20: =IF(U20="Order",A20,"") -> Chilli Powder | AH20: =IF(Z20="Order",A20,"") -> Chilli Powder
A21: Earl grey | B21: 28 | D21: Pack | F21: =IF(B21<=$AA21,"Order","") | I21: Pack | K21: =IF(G21<=$AA21,"Order","") -> Order | N21: Pack | P21: =IF(L21<=$AA21,"Order","") -> Order | S21: Pack | U21: =IF(Q21<=$AA21,"Order","") -> Order | X21: Pack | Z21: =IF(V21<=$AA21,"Order","") -> Order | AA21: 6 | AD21: =IF(F21="Order",A21,"") | AE21: =IF(K21="Order",A21,"") -> Earl grey | AF21: =IF(P21="Order",A21,"") -> Earl grey | AG21: =IF(U21="Order",A21,"") -> Earl grey | AH21: =IF(Z21="Order",A21,"") -> Earl grey
A22: Thai Milk Tea | B22: 10 | D22: Pack | F22: =IF(B22<=$AA22,"Order","") -> Order | I22: Pack | K22: =IF(G22<=$AA22,"Order","") -> Order | N22: Pack | P22: =IF(L22<=$AA22,"Order","") -> Order | S22: Pack | U22: =IF(Q22<=$AA22,"Order","") -> Order | X22: Pack | Z22: =IF(V22<=$AA22,"Order","") -> Order | AA22: 15 | AD22: =IF(F22="Order",A22,"") -> Thai Milk Tea | AE22: =IF(K22="Order",A22,"") -> Thai Milk Tea | AF22: =IF(P22="Order",A22,"") -> Thai Milk Tea | AG22: =IF(U22="Order",A22,"") -> Thai Milk Tea | AH22: =IF(Z22="Order",A22,"") -> Thai Milk Tea
A23: Thai Green Tea | B23: 23 | D23: Pack | F23: =IF(B23<=$AA23,"Order","") | I23: Pack | K23: =IF(G23<=$AA23,"Order","") -> Order | N23: Pack | P23: =IF(L23<=$AA23,"Order","") -> Order | S23: Pack | U23: =IF(Q23<=$AA23,"Order","") -> Order | X23: Pack | Z23: =IF(V23<=$AA23,"Order","") -> Order | AA23: 15 | AD23: =IF(F23="Order",A23,"") | AE23: =IF(K23="Order",A23,"") -> Thai Green Tea | AF23: =IF(P23="Order",A23,"") -> Thai Green Tea | AG23: =IF(U23="Order",A23,"") -> Thai Green Tea | AH23: =IF(Z23="Order",A23,"") -> Thai Green Tea
A24: Cheezy Powder | B24: 6 | D24: Pack | F24: =IF(B24<=$AA24,"Order","") -> Order | I24: Pack | K24: =IF(G24<=$AA24,"Order","") -> Order | N24: Pack | P24: =IF(L24<=$AA24,"Order","") -> Order | S24: Pack | U24: =IF(Q24<=$AA24,"Order","") -> Order | X24: Pack | Z24: =IF(V24<=$AA24,"Order","") -> Order | AA24: 10 | AD24: =IF(F24="Order",A24,"") -> Cheezy Powder | AE24: =IF(K24="Order",A24,"") -> Cheezy Powder | AF24: =IF(P24="Order",A24,"") -> Cheezy Powder | AG24: =IF(U24="Order",A24,"") -> Cheezy Powder | AH24: =IF(Z24="Order",A24,"") -> Cheezy Powder
A25: Evaporated Milk (CARNATION) [48/CTN] | B25: 2 | C25: Ctn | D25: 0 | E25: Can | F25: =IF(((B25*48)+D25)<=$AA25,"Order","") | H25: Ctn | J25: Can | K25: =IF(((G25*48)+I25)<=$AA25,"Order","") -> Order | M25: Ctn | O25: Can | P25: =IF(((L25*48)+N25)<=$AA25,"Order","") -> Order | R25: Ctn | T25: Can | U25: =IF(((Q25*48)+S25)<=$AA25,"Order","") -> Order | W25: Ctn | Y25: Can | Z25: =IF(((V25*48)+X25)<=$AA25,"Order","") -> Order | AA25: 84 | AD25: =IF(F25="Order",A25,"") | AE25: =IF(K25="Order",A25,"") -> Evaporated Milk (CARNATION) [48/CTN] | AF25: =IF(P25="Order",A25,"") -> Evaporated Milk (CARNATION) [48/CTN] | AG25: =IF(U25="Order",A25,"") -> Evaporated Milk (CARNATION) [48/CTN] | AH25: =IF(Z25="Order",A25,"") -> Evaporated Milk (CARNATION) [48/CTN]
A26: Sweetened Milk (TEAPOT) | B26: 1 | C26: Ctn | D26: 3 | E26: Pack | F26: =IF(((B26*4)+D26)<=$AA26,"Order","") -> Order | H26: Ctn | J26: Pack | K26: =IF(((G26*4)+I26)<=$AA26,"Order","") -> Order | M26: Ctn | O26: Pack | P26: =IF(((L26*4)+N26)<=$AA26,"Order","") -> Order | R26: Ctn | T26: Pack | U26: =IF(((Q26*4)+S26)<=$AA26,"Order","") -> Order | W26: Ctn | Y26: Pack | Z26: =IF(((V26*4)+X26)<=$AA26,"Order","") -> Order | AA26: 8 | AD26: =IF(F26="Order",A26,"") -> Sweetened Milk (TEAPOT) | AE26: =IF(K26="Order",A26,"") -> Sweetened Milk (TEAPOT) | AF26: =IF(P26="Order",A26,"") -> Sweetened Milk (TEAPOT) | AG26: =IF(U26="Order",A26,"") -> Sweetened Milk (TEAPOT) | AH26: =IF(Z26="Order",A26,"") -> Sweetened Milk (TEAPOT)
A27: Coffee Mate (NESTLE) - 1KG | B27: 3 | D27: Pack | F27: =IF(B27<=$AA27,"Order","") -> Order | I27: Pack | K27: =IF(G27<=$AA27,"Order","") -> Order | N27: Pack | P27: =IF(L27<=$AA27,"Order","") -> Order | S27: Pack | U27: =IF(Q27<=$AA27,"Order","") -> Order | X27: Pack | Z27: =IF(V27<=$AA27,"Order","") -> Order | AA27: 25 | AD27: =IF(F27="Order",A27,"") -> Coffee Mate (NESTLE) - 1KG | AE27: =IF(K27="Order",A27,"") -> Coffee Mate (NESTLE) - 1KG | AF27: =IF(P27="Order",A27,"") -> Coffee Mate (NESTLE) - 1KG | AG27: =IF(U27="Order",A27,"") -> Coffee Mate (NESTLE) - 1KG | AH27: =IF(Z27="Order",A27,"") -> Coffee Mate (NESTLE) - 1KG
A28: Pork/ Chicken Powder (3KG MIX) | B28: 1 | D28: Pack | F28: =IF(B28<=$AA28,"Order","") -> Order | I28: Pack | K28: =IF(G28<=$AA28,"Order","") -> Order | N28: Pack | P28: =IF(L28<=$AA28,"Order","") -> Order | S28: Pack | U28: =IF(Q28<=$AA28,"Order","") -> Order | X28: Pack | Z28: =IF(V28<=$AA28,"Order","") -> Order | AA28: 3 | AD28: =IF(F28="Order",A28,"") -> Pork/ Chicken Powder (3KG MIX) | AE28: =IF(K28="Order",A28,"") -> Pork/ Chicken Powder (3KG MIX) | AF28: =IF(P28="Order",A28,"") -> Pork/ Chicken Powder (3KG MIX) | AG28: =IF(U28="Order",A28,"") -> Pork/ Chicken Powder (3KG MIX) | AH28: =IF(Z28="Order",A28,"") -> Pork/ Chicken Powder (3KG MIX)
A29: Pork/ Chicken Powder (6KG MIX) | B29: 1 | D29: Pack | F29: =IF(B29<=$AA29,"Order","") -> Order | I29: Pack | K29: =IF(G29<=$AA29,"Order","") -> Order | N29: Pack | P29: =IF(L29<=$AA29,"Order","") -> Order | S29: Pack | U29: =IF(Q29<=$AA29,"Order","") -> Order | X29: Pack | Z29: =IF(V29<=$AA29,"Order","") -> Order | AA29: 3 | AD29: =IF(F29="Order",A29,"") -> Pork/ Chicken Powder (6KG MIX) | AE29: =IF(K29="Order",A29,"") -> Pork/ Chicken Powder (6KG MIX) | AF29: =IF(P29="Order",A29,"") -> Pork/ Chicken Powder (6KG MIX) | AG29: =IF(U29="Order",A29,"") -> Pork/ Chicken Powder (6KG MIX) | AH29: =IF(Z29="Order",A29,"") -> Pork/ Chicken Powder (6KG MIX)
A30: Pork/ Chicken Powder (12KG MIX) | B30: 0 | D30: Pack | F30: =IF(B30<=$AA30,"Order","") -> Order | I30: Pack | K30: =IF(G30<=$AA30,"Order","") -> Order | N30: Pack | P30: =IF(L30<=$AA30,"Order","") -> Order | S30: Pack | U30: =IF(Q30<=$AA30,"Order","") -> Order | X30: Pack | Z30: =IF(V30<=$AA30,"Order","") -> Order | AA30: 5 | AD30: =IF(F30="Order",A30,"") -> Pork/ Chicken Powder (12KG MIX) | AE30: =IF(K30="Order",A30,"") -> Pork/ Chicken Powder (12KG MIX) | AF30: =IF(P30="Order",A30,"") -> Pork/ Chicken Powder (12KG MIX) | AG30: =IF(U30="Order",A30,"") -> Pork/ Chicken Powder (12KG MIX) | AH30: =IF(Z30="Order",A30,"") -> Pork/ Chicken Powder (12KG MIX)
A31: Beef Powder (6KG MIX) | B31: 0 | D31: Pack | F31: =IF(B31<=$AA31,"Order","") -> Order | I31: Pack | K31: =IF(G31<=$AA31,"Order","") -> Order | N31: Pack | P31: =IF(L31<=$AA31,"Order","") -> Order | S31: Pack | U31: =IF(Q31<=$AA31,"Order","") -> Order | X31: Pack | Z31: =IF(V31<=$AA31,"Order","") -> Order | AA31: 5 | AD31: =IF(F31="Order",A31,"") -> Beef Powder (6KG MIX) | AE31: =IF(K31="Order",A31,"") -> Beef Powder (6KG MIX) | AF31: =IF(P31="Order",A31,"") -> Beef Powder (6KG MIX) | AG31: =IF(U31="Order",A31,"") -> Beef Powder (6KG MIX) | AH31: =IF(Z31="Order",A31,"") -> Beef Powder (6KG MIX)
A32: Yuzu Premix | B32: 0 | D32: Pack | F32: =IF(B32<=$AA32,"Order","") -> Order | I32: Pack | K32: =IF(G32<=$AA32,"Order","") -> Order | N32: Pack | P32: =IF(L32<=$AA32,"Order","") -> Order | S32: Pack | U32: =IF(Q32<=$AA32,"Order","") -> Order | X32: Pack | Z32: =IF(V32<=$AA32,"Order","") -> Order | AA32: 8 | AD32: =IF(F32="Order",A32,"") -> Yuzu Premix | AE32: =IF(K32="Order",A32,"") -> Yuzu Premix | AF32: =IF(P32="Order",A32,"") -> Yuzu Premix | AG32: =IF(U32="Order",A32,"") -> Yuzu Premix | AH32: =IF(Z32="Order",A32,"") -> Yuzu Premix
A33: S. Yuzu Premix | B33: 4 | D33: Pack | F33: =IF(B33<=$AA33,"Order","") -> Order | I33: Pack | K33: =IF(G33<=$AA33,"Order","") -> Order | N33: Pack | P33: =IF(L33<=$AA33,"Order","") -> Order | S33: Pack | U33: =IF(Q33<=$AA33,"Order","") -> Order | X33: Pack | Z33: =IF(V33<=$AA33,"Order","") -> Order | AA33: 8 | AD33: =IF(F33="Order",A33,"") -> S. Yuzu Premix | AE33: =IF(K33="Order",A33,"") -> S. Yuzu Premix | AF33: =IF(P33="Order",A33,"") -> S. Yuzu Premix | AG33: =IF(U33="Order",A33,"") -> S. Yuzu Premix | AH33: =IF(Z33="Order",A33,"") -> S. Yuzu Premix
A34: Yuzu Coating Powder | B34: 1 | D34: Pack | F34: =IF(B34<=$AA34,"Order","") -> Order | I34: Pack | K34: =IF(G34<=$AA34,"Order","") -> Order | N34: Pack | P34: =IF(L34<=$AA34,"Order","") -> Order | S34: Pack | U34: =IF(Q34<=$AA34,"Order","") -> Order | X34: Pack | Z34: =IF(V34<=$AA34,"Order","") -> Order | AA34: 2 | AD34: =IF(F34="Order",A34,"") -> Yuzu Coating Powder | AE34: =IF(K34="Order",A34,"") -> Yuzu Coating Powder | AF34: =IF(P34="Order",A34,"") -> Yuzu Coating Powder | AG34: =IF(U34="Order",A34,"") -> Yuzu Coating Powder | AH34: =IF(Z34="Order",A34,"") -> Yuzu Coating Powder
A35: S.Yuzu Coating Powder | B35: 1 | D35: Pack | F35: =IF(B35<=$AA35,"Order","") -> Order | I35: Pack | K35: =IF(G35<=$AA35,"Order","") -> Order | N35: Pack | P35: =IF(L35<=$AA35,"Order","") -> Order | S35: Pack | U35: =IF(Q35<=$AA35,"Order","") -> Order | X35: Pack | Z35: =IF(V35<=$AA35,"Order","") -> Order | AA35: 2 | AD35: =IF(F35="Order",A35,"") -> S.Yuzu Coating Powder | AE35: =IF(K35="Order",A35,"") -> S.Yuzu Coating Powder | AF35: =IF(P35="Order",A35,"") -> S.Yuzu Coating Powder | AG35: =IF(U35="Order",A35,"") -> S.Yuzu Coating Powder | AH35: =IF(Z35="Order",A35,"") -> S.Yuzu Coating Powder
A36: Ogoma Sauce | B36: 1 | D36: Pack | F36: =IF(B36<=$AA36,"Order","") | I36: Pack | K36: =IF(G36<=$AA36,"Order","") -> Order | N36: Pack | P36: =IF(L36<=$AA36,"Order","") -> Order | S36: Pack | U36: =IF(Q36<=$AA36,"Order","") -> Order | X36: Pack | Z36: =IF(V36<=$AA36,"Order","") -> Order | AA36: 0.5 | AD36: =IF(F36="Order",A36,"") | AE36: =IF(K36="Order",A36,"") -> Ogoma Sauce | AF36: =IF(P36="Order",A36,"") -> Ogoma Sauce | AG36: =IF(U36="Order",A36,"") -> Ogoma Sauce | AH36: =IF(Z36="Order",A36,"") -> Ogoma Sauce
A37: SSS Sauce | B37: 1.1 | D37: Pack | F37: =IF(B37<=$AA37,"Order","") | I37: Pack | K37: =IF(G37<=$AA37,"Order","") -> Order | N37: Pack | P37: =IF(L37<=$AA37,"Order","") -> Order | S37: Pack | U37: =IF(Q37<=$AA37,"Order","") -> Order | X37: Pack | Z37: =IF(V37<=$AA37,"Order","") -> Order | AA37: 0.5 | AD37: =IF(F37="Order",A37,"") | AE37: =IF(K37="Order",A37,"") -> SSS Sauce | AF37: =IF(P37="Order",A37,"") -> SSS Sauce | AG37: =IF(U37="Order",A37,"") -> SSS Sauce | AH37: =IF(Z37="Order",A37,"") -> SSS Sauce
A38: Yuzu Sauce | B38: 1 | D38: Pack | F38: =IF(B38<=$AA38,"Order","") | I38: Pack | K38: =IF(G38<=$AA38,"Order","") -> Order | N38: Pack | P38: =IF(L38<=$AA38,"Order","") -> Order | S38: Pack | U38: =IF(Q38<=$AA38,"Order","") -> Order | X38: Pack | Z38: =IF(V38<=$AA38,"Order","") -> Order | AA38: 0.5 | AD38: =IF(F38="Order",A38,"") | AE38: =IF(K38="Order",A38,"") -> Yuzu Sauce | AF38: =IF(P38="Order",A38,"") -> Yuzu Sauce | AG38: =IF(U38="Order",A38,"") -> Yuzu Sauce | AH38: =IF(Z38="Order",A38,"") -> Yuzu Sauce
... A43: Mentaiko Sauce | B43: 9 | D43: Pack | F43: =IF(B43<=$AA43,"Order","") | I43: Pack | K43: =IF(G43<=$AA43,"Order","") -> Order | N43: Pack | P43: =IF(L43<=$AA43,"Order","") -> Order | S43: Pack | U43: =IF(Q43<=$AA43,"Order","") -> Order | X43: Pack | Z43: =IF(V43<=$AA43,"Order","") -> Order | AA43: 1 | AD43: =IF(F43="Order",A43,"") | AE43: =IF(K43="Order",A43,"") -> Mentaiko Sauce | AF43: =IF(P43="Order",A43,"") -> Mentaiko Sauce | AG43: =IF(U43="Order",A43,"") -> Mentaiko Sauce | AH43: =IF(Z43="Order",A43,"") -> Mentaiko Sauce
A50: =IF(B2="","",TEXTJOIN(" , ",TRUE,AD4:AD43)) -> #NAME?
...

Sheet Untensil PG1
A1: Untensil Inventory listing 2026 (WEEKLY STOCK)
A2: ITEM | B2: 46213 | Q2: Minimun Order Quantity
B3: Quantity ＆ Unit | D3: Status | E3: Quantity ＆ Unit | G3: Status | H3: Quantity ＆ Unit | J3: Status | K3: Quantity ＆ Unit | M3: Status | N3: Quantity ＆ Unit | P3: Status
A4: Singlet Bag (8' x 12' 500g) | B4: 4 | C4: Pack | D4: =IF(B4<=$Q4,"Order","") -> Order | F4: Pack | G4: =IF(E4<=$Q4,"Order","") -> Order | I4: Pack | J4: =IF(H4<=$Q4,"Order","") -> Order | L4: Pack | M4: =IF(K4<=$Q4,"Order","") -> Order | O4: Pack | P4: =IF(N4<=$Q4,"Order","") -> Order | Q4: 4 | S4: =IF(D4="Order",A4,"") -> Singlet Bag (8' x 12' 500g) | T4: =IF(G4="Order",A4,"") -> Singlet Bag (8' x 12' 500g) | U4: =IF(J4="Order",A4,"") -> Singlet Bag (8' x 12' 500g) | V4: =IF(M4="Order",A4,"") -> Singlet Bag (8' x 12' 500g) | W4: =IF(P4="Order",A4,"") -> Singlet Bag (8' x 12' 500g)
A5: PE Singlet Bag (11' x 15' 500g) | B5: 5 | C5: Pack | D5: =IF(B5<=$Q5,"Order","") | F5: Pack | G5: =IF(E5<=Q5,"Order","") -> Order | I5: Pack | J5: =IF(H5<=$Q5,"Order","") -> Order | L5: Pack | M5: =IF(K5<=$Q5,"Order","") -> Order | O5: Pack | P5: =IF(N5<=$Q5,"Order","") -> Order | Q5: 4 | S5: =IF(D5="Order",A5,"") | T5: =IF(G5="Order",A5,"") -> PE Singlet Bag (11' x 15' 500g) | U5: =IF(J5="Order",A5,"") -> PE Singlet Bag (11' x 15' 500g) | V5: =IF(M5="Order",A5,"") -> PE Singlet Bag (11' x 15' 500g) | W5: =IF(P5="Order",A5,"") -> PE Singlet Bag (11' x 15' 500g)
A6: PE Singlet Bag (13' x 15' 500g) | B6: 4 | C6: Pack | D6: =IF(B6<=$Q6,"Order","") | F6: Pack | G6: =IF(E6<=Q6,"Order","") -> Order | I6: Pack | J6: =IF(H6<=$Q6,"Order","") -> Order | L6: Pack | M6: =IF(K6<=$Q6,"Order","") -> Order | O6: Pack | P6: =IF(N6<=$Q6,"Order","") -> Order | Q6: 3 | S6: =IF(D6="Order",A6,"") | T6: =IF(G6="Order",A6,"") -> PE Singlet Bag (13' x 15' 500g) | U6: =IF(J6="Order",A6,"") -> PE Singlet Bag (13' x 15' 500g) | V6: =IF(M6="Order",A6,"") -> PE Singlet Bag (13' x 15' 500g) | W6: =IF(P6="Order",A6,"") -> PE Singlet Bag (13' x 15' 500g)
A7: CPE / HD 1 Cup Holder Bag (200pcs) | B7: 12 | C7: Pack | D7: =IF(B7<=$Q7,"Order","") | F7: Pack | G7: =IF(E7<=Q7,"Order","") -> Order | I7: Pack | J7: =IF(H7<=$Q7,"Order","") -> Order | L7: Pack | M7: =IF(K7<=$Q7,"Order","") -> Order | O7: Pack | P7: =IF(N7<=$Q7,"Order","") -> Order | Q7: 3 | S7: =IF(D7="Order",A7,"") | T7: =IF(G7="Order",A7,"") -> CPE / HD 1 Cup Holder Bag (200pcs) | U7: =IF(J7="Order",A7,"") -> CPE / HD 1 Cup Holder Bag (200pcs) | V7: =IF(M7="Order",A7,"") -> CPE / HD 1 Cup Holder Bag (200pcs) | W7: =IF(P7="Order",A7,"") -> CPE / HD 1 Cup Holder Bag (200pcs)
A8: CPE / HD 2 Cup Holder Bag (200pcs) | B8: 5 | C8: Pack | D8: =IF(B8<=$Q8,"Order","") | F8: Pack | G8: =IF(E8<=Q8,"Order","") -> Order | I8: Pack | J8: =IF(H8<=$Q8,"Order","") -> Order | L8: Pack | M8: =IF(K8<=$Q8,"Order","") -> Order | O8: Pack | P8: =IF(N8<=$Q8,"Order","") -> Order | Q8: 2 | S8: =IF(D8="Order",A8,"") | T8: =IF(G8="Order",A8,"") -> CPE / HD 2 Cup Holder Bag (200pcs) | U8: =IF(J8="Order",A8,"") -> CPE / HD 2 Cup Holder Bag (200pcs) | V8: =IF(M8="Order",A8,"") -> CPE / HD 2 Cup Holder Bag (200pcs) | W8: =IF(P8="Order",A8,"") -> CPE / HD 2 Cup Holder Bag (200pcs)
A9: Medium Cup (AP 160z PP Cup) | B9: 1 | C9: Pack | D9: =IF(B9<=$Q9,"Order","") -> Order | F9: Pack | G9: =IF(E9<=Q9,"Order","") -> Order | I9: Pack | J9: =IF(H9<=$Q9,"Order","") -> Order | L9: Pack | M9: =IF(K9<=$Q9,"Order","") -> Order | O9: Pack | P9: =IF(N9<=$Q9,"Order","") -> Order | Q9: 5 | S9: =IF(D9="Order",A9,"") -> Medium Cup (AP 160z PP Cup) | T9: =IF(G9="Order",A9,"") -> Medium Cup (AP 160z PP Cup) | U9: =IF(J9="Order",A9,"") -> Medium Cup (AP 160z PP Cup) | V9: =IF(M9="Order",A9,"") -> Medium Cup (AP 160z PP Cup) | W9: =IF(P9="Order",A9,"") -> Medium Cup (AP 160z PP Cup)
A10: Large Cup (700 PP Cup) | B10: 3 | C10: Pack | D10: =IF(B10<=$Q10,"Order","") -> Order | F10: Pack | G10: =IF(E10<=Q10,"Order","") -> Order | I10: Pack | J10: =IF(H10<=$Q10,"Order","") -> Order | L10: Pack | M10: =IF(K10<=$Q10,"Order","") -> Order | O10: Pack | P10: =IF(N10<=$Q10,"Order","") -> Order | Q10: 5 | S10: =IF(D10="Order",A10,"") -> Large Cup (700 PP Cup) | T10: =IF(G10="Order",A10,"") -> Large Cup (700 PP Cup) | U10: =IF(J10="Order",A10,"") -> Large Cup (700 PP Cup) | V10: =IF(M10="Order",A10,"") -> Large Cup (700 PP Cup) | W10: =IF(P10="Order",A10,"") -> Large Cup (700 PP Cup)
A11: Medium Dome Lid (Ap Dome Lid) | B11: 9 | C11: Pack | D11: =IF(B11<=$Q11,"Order","") | F11: Pack | G11: =IF(E11<=Q11,"Order","") -> Order | I11: Pack | J11: =IF(H11<=$Q11,"Order","") -> Order | L11: Pack | M11: =IF(K11<=$Q11,"Order","") -> Order | O11: Pack | P11: =IF(N11<=$Q11,"Order","") -> Order | Q11: 5 | S11: =IF(D11="Order",A11,"") | T11: =IF(G11="Order",A11,"") -> Medium Dome Lid (Ap Dome Lid) | U11: =IF(J11="Order",A11,"") -> Medium Dome Lid (Ap Dome Lid) | V11: =IF(M11="Order",A11,"") -> Medium Dome Lid (Ap Dome Lid) | W11: =IF(P11="Order",A11,"") -> Medium Dome Lid (Ap Dome Lid)
A12: Large Dome Lid (AO Dome Lid) | B12: 8 | C12: Pack | D12: =IF(B12<=$Q12,"Order","") | F12: Pack | G12: =IF(E12<=Q12,"Order","") -> Order | I12: Pack | J12: =IF(H12<=$Q12,"Order","") -> Order | L12: Pack | M12: =IF(K12<=$Q12,"Order","") -> Order | O12: Pack | P12: =IF(N12<=$Q12,"Order","") -> Order | Q12: 5 | S12: =IF(D12="Order",A12,"") | T12: =IF(G12="Order",A12,"") -> Large Dome Lid (AO Dome Lid) | U12: =IF(J12="Order",A12,"") -> Large Dome Lid (AO Dome Lid) | V12: =IF(M12="Order",A12,"") -> Large Dome Lid (AO Dome Lid) | W12: =IF(P12="Order",A12,"") -> Large Dome Lid (AO Dome Lid)
A13: Large Flat Lid (AO Lid) | B13: 9 | C13: Pack | D13: =IF(B13<=$Q13,"Order","") | F13: Pack | G13: =IF(E13<=Q13,"Order","") -> Order | I13: Pack | J13: =IF(H13<=$Q13,"Order","") -> Order | L13: Pack | M13: =IF(K13<=$Q13,"Order","") -> Order | O13: Pack | P13: =IF(N13<=$Q13,"Order","") -> Order | Q13: 5 | S13: =IF(D13="Order",A13,"") | T13: =IF(G13="Order",A13,"") -> Large Flat Lid (AO Lid) | U13: =IF(J13="Order",A13,"") -> Large Flat Lid (AO Lid) | V13: =IF(M13="Order",A13,"") -> Large Flat Lid (AO Lid) | W13: =IF(P13="Order",A13,"") -> Large Flat Lid (AO Lid)
A14: Hot Cup Lid (10 Pack Per Cttn) | B14: 24 | C14: Pack | D14: =IF(B14<=$Q14,"Order","") | F14: Pack | G14: =IF(E14<=Q14,"Order","") -> Order | I14: Pack | J14: =IF(H14<=$Q14,"Order","") -> Order | L14: Pack | M14: =IF(K14<=$Q14,"Order","") -> Order | O14: Pack | P14: =IF(N14<=$Q14,"Order","") -> Order | Q14: 10 | S14: =IF(D14="Order",A14,"") | T14: =IF(G14="Order",A14,"") -> Hot Cup Lid (10 Pack Per Cttn) | U14: =IF(J14="Order",A14,"") -> Hot Cup Lid (10 Pack Per Cttn) | V14: =IF(M14="Order",A14,"") -> Hot Cup Lid (10 Pack Per Cttn) | W14: =IF(P14="Order",A14,"") -> Hot Cup Lid (10 Pack Per Cttn)
A15: 10a Double Layer Hot Cup (20 Pack/ Ctn) | B15: 13 | C15: Pack | D15: =IF(B15<=$Q15,"Order","") | F15: Pack | G15: =IF(E15<=Q15,"Order","") -> Order | I15: Pack | J15: =IF(H15<=$Q15,"Order","") -> Order | L15: Pack | M15: =IF(K15<=$Q15,"Order","") -> Order | O15: Pack | P15: =IF(N15<=$Q15,"Order","") -> Order | Q15: 10 | S15: =IF(D15="Order",A15,"") | T15: =IF(G15="Order",A15,"") -> 10a Double Layer Hot Cup (20 Pack/ Ctn) | U15: =IF(J15="Order",A15,"") -> 10a Double Layer Hot Cup (20 Pack/ Ctn) | V15: =IF(M15="Order",A15,"") -> 10a Double Layer Hot Cup (20 Pack/ Ctn) | W15: =IF(P15="Order",A15,"") -> 10a Double Layer Hot Cup (20 Pack/ Ctn)
A16: Large Double Layer Hot Cup (20 Pack/ Ctn) | B16: 23 | C16: Pack | D16: =IF(B16<=$Q16,"Order","") | F16: Pack | G16: =IF(E16<=Q16,"Order","") -> Order | I16: Pack | J16: =IF(H16<=$Q16,"Order","") -> Order | L16: Pack | M16: =IF(K16<=$Q16,"Order","") -> Order | O16: Pack | P16: =IF(N16<=$Q16,"Order","") -> Order | Q16: 10 | S16: =IF(D16="Order",A16,"") | T16: =IF(G16="Order",A16,"") -> Large Double Layer Hot Cup (20 Pack/ Ctn) | U16: =IF(J16="Order",A16,"") -> Large Double Layer Hot Cup (20 Pack/ Ctn) | V16: =IF(M16="Order",A16,"") -> Large Double Layer Hot Cup (20 Pack/ Ctn) | W16: =IF(P16="Order",A16,"") -> Large Double Layer Hot Cup (20 Pack/ Ctn)
... A21: Plastic Bag FF Large (S/B 24x28) Red | B21: 0.5 | C21: Pack | D21: =IF(B21<=$Q21,"Order","") -> Order | F21: Pack | G21: =IF(E21<=Q21,"Order","") -> Order | I21: Pack | J21: =IF(H21<=$Q21,"Order","") -> Order | L21: Pack | M21: =IF(K21<=$Q21,"Order","") -> Order | O21: Pack | P21: =IF(N21<=$Q21,"Order","") -> Order | Q21: 0.5 | S21: =IF(D21="Order",A21,"") -> Plastic Bag FF Large (S/B 24x28) Red | T21: =IF(G21="Order",A21,"") -> Plastic Bag FF Large (S/B 24x28) Red | U21: =IF(J21="Order",A21,"") -> Plastic Bag FF Large (S/B 24x28) Red | V21: =IF(M21="Order",A21,"") -> Plastic Bag FF Large (S/B 24x28) Red | W21: =IF(P21="Order",A21,"") -> Plastic Bag FF Large (S/B 24x28) Red
A22: Plastic Bag 8 x 12 500G (White) | B22: 0.3 | C22: Pack | D22: =IF(B22<=$Q22,"Order","") -> Order | F22: Pack | G22: =IF(E22<=Q22,"Order","") -> Order | I22: Pack | J22: =IF(H22<=$Q22,"Order","") -> Order | L22: Pack | M22: =IF(K22<=$Q22,"Order","") -> Order | O22: Pack | P22: =IF(N22<=$Q22,"Order","") -> Order | Q22: 0.5
A23: Plastic Bag 8 x 12 500G (Red) | B23: 2.1 | C23: Pack | D23: =IF(B23<=$Q23,"Order","") | F23: Pack | G23: =IF(E23<=Q23,"Order","") -> Order | I23: Pack | J23: =IF(H23<=$Q23,"Order","") -> Order | L23: Pack | M23: =IF(K23<=$Q23,"Order","") -> Order | O23: Pack | P23: =IF(N23<=$Q23,"Order","") -> Order | Q23: 0.5
A24: HD pkt 5'x8' @ 500g | B24: 1 | C24: Pack | D24: =IF(B24<=$Q24,"Order","") | F24: Pack | G24: =IF(E24<=Q24,"Order","") -> Order | I24: Pack | J24: =IF(H24<=$Q24,"Order","") -> Order | L24: Pack | M24: =IF(K24<=$Q24,"Order","") -> Order | O24: Pack | P24: =IF(N24<=$Q24,"Order","") -> Order | Q24: 0.5 | S24: =IF(D24="Order",A24,"") | T24: =IF(G24="Order",A24,"") -> HD pkt 5'x8' @ 500g | U24: =IF(J24="Order",A24,"") -> HD pkt 5'x8' @ 500g | V24: =IF(M24="Order",A24,"") -> HD pkt 5'x8' @ 500g | W24: =IF(P24="Order",A24,"") -> HD pkt 5'x8' @ 500g
A25: HD pkt 7x10' @ 1kg | B25: 1.5 | C25: Pack | D25: =IF(B25<=$Q25,"Order","") | F25: Pack | G25: =IF(E25<=Q25,"Order","") -> Order | I25: Pack | J25: =IF(H25<=$Q25,"Order","") -> Order | L25: Pack | M25: =IF(K25<=$Q25,"Order","") -> Order | O25: Pack | P25: =IF(N25<=$Q25,"Order","") -> Order | Q25: 0.5 | S25: =IF(D25="Order",A25,"") | T25: =IF(G25="Order",A25,"") -> HD pkt 7x10' @ 1kg | U25: =IF(J25="Order",A25,"") -> HD pkt 7x10' @ 1kg | V25: =IF(M25="Order",A25,"") -> HD pkt 7x10' @ 1kg | W25: =IF(P25="Order",A25,"") -> HD pkt 7x10' @ 1kg
A26: Paper Bag (4" Brown Paper 100's) | B26: 1 | C26: Pack | D26: =IF(B26<=$Q26,"Order","") -> Order | F26: Pack | G26: =IF(E26<=Q26,"Order","") -> Order | I26: Pack | J26: =IF(H26<=$Q26,"Order","") -> Order | L26: Pack | M26: =IF(K26<=$Q26,"Order","") -> Order | O26: Pack | P26: =IF(N26<=$Q26,"Order","") -> Order | Q26: 5 | S26: =IF(D26="Order",A26,"") -> Paper Bag (4" Brown Paper 100's) | T26: =IF(G26="Order",A26,"") -> Paper Bag (4" Brown Paper 100's) | U26: =IF(J26="Order",A26,"") -> Paper Bag (4" Brown Paper 100's) | V26: =IF(M26="Order",A26,"") -> Paper Bag (4" Brown Paper 100's) | W26: =IF(P26="Order",A26,"") -> Paper Bag (4" Brown Paper 100's)
A27: Paper Bag (4" White Paper Bag) | B27: 1 | C27: Pack | D27: =IF(B27<=$Q27,"Order","") -> Order | F27: Pack | G27: =IF(E27<=Q27,"Order","") -> Order | I27: Pack | J27: =IF(H27<=$Q27,"Order","") -> Order | L27: Pack | M27: =IF(K27<=$Q27,"Order","") -> Order | O27: Pack | P27: =IF(N27<=$Q27,"Order","") -> Order | Q27: 5 | S27: =IF(D27="Order",A27,"") -> Paper Bag (4" White Paper Bag) | T27: =IF(G27="Order",A27,"") -> Paper Bag (4" White Paper Bag) | U27: =IF(J27="Order",A27,"") -> Paper Bag (4" White Paper Bag) | V27: =IF(M27="Order",A27,"") -> Paper Bag (4" White Paper Bag) | W27: =IF(P27="Order",A27,"") -> Paper Bag (4" White Paper Bag)
A28: ABBA Food Paper Tray | B28: 2 | C28: Pack | D28: =IF(B28<=$Q28,"Order","") -> Order | F28: Pack | G28: =IF(E28<=Q28,"Order","") -> Order | I28: Pack | J28: =IF(H28<=$Q28,"Order","") -> Order | L28: Pack | M28: =IF(K28<=$Q28,"Order","") -> Order | O28: Pack | P28: =IF(N28<=$Q28,"Order","") -> Order | Q28: 5 | S28: =IF(D28="Order",A28,"") -> ABBA Food Paper Tray | T28: =IF(G28="Order",A28,"") -> ABBA Food Paper Tray | U28: =IF(J28="Order",A28,"") -> ABBA Food Paper Tray | V28: =IF(M28="Order",A28,"") -> ABBA Food Paper Tray | W28: =IF(P28="Order",A28,"") -> ABBA Food Paper Tray
A29: Y500 Black Rec | B29: 1 | C29: Pack | D29: =IF(B29<=$Q29,"Order","") -> Order | F29: Pack | G29: =IF(E29<=Q29,"Order","") -> Order | I29: Pack | J29: =IF(H29<=$Q29,"Order","") -> Order | L29: Pack | M29: =IF(K29<=$Q29,"Order","") -> Order | O29: Pack | P29: =IF(N29<=$Q29,"Order","") -> Order | Q29: 4 | S29: =IF(D29="Order",A29,"") -> Y500 Black Rec | T29: =IF(G29="Order",A29,"") -> Y500 Black Rec | U29: =IF(J29="Order",A29,"") -> Y500 Black Rec | V29: =IF(M29="Order",A29,"") -> Y500 Black Rec | W29: =IF(P29="Order",A29,"") -> Y500 Black Rec
A30: Y750 Black Rec | B30: 2 | C30: Pack | D30: =IF(B30<=$Q30,"Order","") -> Order | F30: Pack | G30: =IF(E30<=Q30,"Order","") -> Order | I30: Pack | J30: =IF(H30<=$Q30,"Order","") -> Order | L30: Pack | M30: =IF(K30<=$Q30,"Order","") -> Order | O30: Pack | P30: =IF(N30<=$Q30,"Order","") -> Order | Q30: 4 | S30: =IF(D30="Order",A30,"") -> Y750 Black Rec | T30: =IF(G30="Order",A30,"") -> Y750 Black Rec | U30: =IF(J30="Order",A30,"") -> Y750 Black Rec | V30: =IF(M30="Order",A30,"") -> Y750 Black Rec | W30: =IF(P30="Order",A30,"") -> Y750 Black Rec
A31: Sauce Plate (BX04) | B31: 1 | C31: Pack | D31: =IF(B31<=$Q31,"Order","") | F31: Pack | G31: =IF(E31<=Q31,"Order","") -> Order | I31: Pack | J31: =IF(H31<=$Q31,"Order","") -> Order | L31: Pack | M31: =IF(K31<=$Q31,"Order","") -> Order | O31: Pack | P31: =IF(N31<=$Q31,"Order","") -> Order | Q31: 0.5 | S31: =IF(D31="Order",A31,"") | T31: =IF(G31="Order",A31,"") -> Sauce Plate (BX04) | U31: =IF(J31="Order",A31,"") -> Sauce Plate (BX04) | V31: =IF(M31="Order",A31,"") -> Sauce Plate (BX04) | W31: =IF(P31="Order",A31,"") -> Sauce Plate (BX04)
A32: Sauce Container Takeaway (BX245) | B32: 1.2 | C32: Pack | D32: =IF(B32<=$Q32,"Order","") | F32: Pack | G32: =IF(E32<=Q32,"Order","") -> Order | I32: Pack | J32: =IF(H32<=$Q32,"Order","") -> Order | L32: Pack | M32: =IF(K32<=$Q32,"Order","") -> Order | O32: Pack | P32: =IF(N32<=$Q32,"Order","") -> Order | Q32: 0.5 | S32: =IF(D32="Order",A32,"") | T32: =IF(G32="Order",A32,"") -> Sauce Container Takeaway (BX245) | U32: =IF(J32="Order",A32,"") -> Sauce Container Takeaway (BX245) | V32: =IF(M32="Order",A32,"") -> Sauce Container Takeaway (BX245) | W32: =IF(P32="Order",A32,"") -> Sauce Container Takeaway (BX245)
A33: Herbal Bag 23x30cm (Earl Grey Fliter) | B33: 1 | C33: Pcs | D33: =IF(B33<=$Q33,"Order","") -> Order | F33: Pcs | G33: =IF(E33<=Q33,"Order","") -> Order | I33: Pcs | J33: =IF(H33<=$Q33,"Order","") -> Order | L33: Pcs | M33: =IF(K33<=$Q33,"Order","") -> Order | O33: Pcs | P33: =IF(N33<=$Q33,"Order","") -> Order | Q33: 1 | S33: =IF(D33="Order",A33,"") -> Herbal Bag 23x30cm (Earl Grey Fliter) | T33: =IF(G33="Order",A33,"") -> Herbal Bag 23x30cm (Earl Grey Fliter) | U33: =IF(J33="Order",A33,"") -> Herbal Bag 23x30cm (Earl Grey Fliter) | V33: =IF(M33="Order",A33,"") -> Herbal Bag 23x30cm (Earl Grey Fliter) | W33: =IF(P33="Order",A33,"") -> Herbal Bag 23x30cm (Earl Grey Fliter)
A34: AA Coffee Filter | B34: 6 | C34: Pcs | D34: =IF(B34<=$Q34,"Order","") | F34: Pcs | G34: =IF(E34<=Q34,"Order","") -> Order | I34: Pcs | J34: =IF(H34<=$Q34,"Order","") -> Order | L34: Pcs | M34: =IF(K34<=$Q34,"Order","") -> Order | O34: Pcs | P34: =IF(N34<=$Q34,"Order","") -> Order | Q34: 2 | S34: =IF(D34="Order",A34,"") | T34: =IF(G34="Order",A34,"") -> AA Coffee Filter | U34: =IF(J34="Order",A34,"") -> AA Coffee Filter | V34: =IF(M34="Order",A34,"") -> AA Coffee Filter | W34: =IF(P34="Order",A34,"") -> AA Coffee Filter
A35: Satay stick ( 14cm/ pack) | B35: 1 | C35: Pack | D35: =IF(B35<=$Q35,"Order","") -> Order | F35: Pack | G35: =IF(E35<=Q35,"Order","") -> Order | I35: Pack | J35: =IF(H35<=$Q35,"Order","") -> Order | L35: Pack | M35: =IF(K35<=$Q35,"Order","") -> Order | O35: Pack | P35: =IF(N35<=$Q35,"Order","") -> Order | Q35: 1 | S35: =IF(D35="Order",A35,"") -> Satay stick ( 14cm/ pack) | T35: =IF(G35="Order",A35,"") -> Satay stick ( 14cm/ pack) | U35: =IF(J35="Order",A35,"") -> Satay stick ( 14cm/ pack) | V35: =IF(M35="Order",A35,"") -> Satay stick ( 14cm/ pack) | W35: =IF(P35="Order",A35,"") -> Satay stick ( 14cm/ pack)
A41: =IF(B2="","",TEXTJOIN(" , ",TRUE,S4:S35)) -> #NAME?
A42: =IF(E2="","",TEXTJOIN(" , ",TRUE,T4:T35))
A43: =IF(H2="","",TEXTJOIN(" , ",TRUE,U4:U35))
A44: =IF(K2="","",TEXTJOIN(" , ",TRUE,V4:V35))
A45: =IF(N2="","",TEXTJOIN(" , ",TRUE,W4:W35))

Sheet Utensil PG2
A1: Untensil Inventory listing 2026 (WEEKLY STOCK)
A2: ITEM | B2: =IF('Untensil PG1'!B2="","",'Untensil PG1'!B2) -> 46213 | E2: =IF('Untensil PG1'!E2="","",'Untensil PG1'!E2) | H2: =IF('Untensil PG1'!H2="","",'Untensil PG1'!H2) | K2: =IF('Untensil PG1'!K2="","",'Untensil PG1'!K2) | N2: =IF('Untensil PG1'!N2="","",'Untensil PG1'!N2) | Q2: Minimun Order Quantity
B3: QTY & Unit | D3: Status | E3: QTY & Unit | G3: Status | H3: QTY & Unit | J3: Status | K3: QTY & Unit | M3: Status | N3: QTY & Unit | P3: Status | T3: =IF(D4="Order",A4,"") | U3: =IF(G4="Order",A4,"") -> Satay stick with SPB logo | V3: =IF(J4="Order",A4,"") -> Satay stick with SPB logo | W3: =IF(M4="Order",A4,"") -> Satay stick with SPB logo | X3: =IF(P4="Order",A4,"") -> Satay stick with SPB logo
A4: Satay stick with SPB logo | B4: 74 | C4: Pack | D4: =IF(B4<=$Q4,"Order","") | F4: Pack | G4: =IF(E4<=$Q4,"Order","") -> Order | I4: Pack | J4: =IF(H4<=$Q4,"Order","") -> Order | L4: Pack | M4: =IF(K4<=$Q4,"Order","") -> Order | O4: Pack | P4: =IF(N4<=$Q4,"Order","") -> Order | Q4: 10 | T4: =IF(D5="Order",A5,"") -> Packing Paper with logo (Yellow) | U4: =IF(G5="Order",A5,"") -> Packing Paper with logo (Yellow) | V4: =IF(J5="Order",A5,"") -> Packing Paper with logo (Yellow) | W4: =IF(M5="Order",A5,"") -> Packing Paper with logo (Yellow) | X4: =IF(P5="Order",A5,"") -> Packing Paper with logo (Yellow)
A5: Packing Paper with logo (Yellow) | B5: 2 | C5: Pack | D5: =IF(B5<=$Q5,"Order","") -> Order | F5: Pack | G5: =IF(E5<=$Q5,"Order","") -> Order | I5: Pack | J5: =IF(H5<=$Q5,"Order","") -> Order | L5: Pack | M5: =IF(K5<=$Q5,"Order","") -> Order | O5: Pack | P5: =IF(N5<=$Q5,"Order","") -> Order | Q5: 7 | T5: =IF(D6="Order",A6,"") | U5: =IF(G6="Order",A6,"") -> Paper cup holder with SPB logo | V5: =IF(J6="Order",A6,"") -> Paper cup holder with SPB logo | W5: =IF(M6="Order",A6,"") -> Paper cup holder with SPB logo | X5: =IF(P6="Order",A6,"") -> Paper cup holder with SPB logo
A6: Paper cup holder with SPB logo | B6: 15 | C6: Bundle | D6: =IF(B6<=$Q6,"Order","") | F6: Bundle | G6: =IF(E6<=$Q6,"Order","") -> Order | I6: Bundle | J6: =IF(H6<=$Q6,"Order","") -> Order | L6: Bundle | M6: =IF(K6<=$Q6,"Order","") -> Order | O6: Bundle | P6: =IF(N6<=$Q6,"Order","") -> Order | Q6: 5 | T6: =IF(D7="Order",A7,"") -> Food Expiring Sticker Label (roll) | U6: =IF(G7="Order",A7,"") -> Food Expiring Sticker Label (roll) | V6: =IF(J7="Order",A7,"") -> Food Expiring Sticker Label (roll) | W6: =IF(M7="Order",A7,"") -> Food Expiring Sticker Label (roll) | X6: =IF(P7="Order",A7,"") -> Food Expiring Sticker Label (roll)
A7: Food Expiring Sticker Label (roll) | B7: 1.5 | C7: Roll | D7: =IF(B7<=$Q7,"Order","") -> Order | F7: Roll | G7: =IF(E7<=$Q7,"Order","") -> Order | I7: Roll | J7: =IF(H7<=$Q7,"Order","") -> Order | L7: Roll | M7: =IF(K7<=$Q7,"Order","") -> Order | O7: Roll | P7: =IF(N7<=$Q7,"Order","") -> Order | Q7: 3 | T7: =IF(D8="Order",A8,"") | U7: =IF(G8="Order",A8,"") -> Logo Solotape | V7: =IF(J8="Order",A8,"") -> Logo Solotape | W7: =IF(M8="Order",A8,"") -> Logo Solotape | X7: =IF(P8="Order",A8,"") -> Logo Solotape
A8: Logo Solotape | B8: 27 | C8: Roll | D8: =IF(B8<=$Q8,"Order","") | F8: Roll | G8: =IF(E8<=$Q8,"Order","") -> Order | I8: Roll | J8: =IF(H8<=$Q8,"Order","") -> Order | L8: Roll | M8: =IF(K8<=$Q8,"Order","") -> Order | O8: Roll | P8: =IF(N8<=$Q8,"Order","") -> Order | Q8: 15 | T8: =IF(D9="Order",A9,"") | U8: =IF(G9="Order",A9,"") | V8: =IF(J9="Order",A9,"") | W8: =IF(M9="Order",A9,"") | X8: =IF(P9="Order",A9,"")
A9: Sticker logo (whole set / pcs) | B9: 17 | C9: Pcs | D9: =IF(B9<=0,"No More Use","") | F9: Pcs | G9: =IF(E9<=0,"No More Use","") -> No More Use | I9: Pcs | J9: =IF(H9<=0,"No More Use","") -> No More Use | L9: Pcs | M9: =IF(K9<=0,"No More Use","") -> No More Use | O9: Pcs | P9: =IF(N9<=0,"No More Use","") -> No More Use | T9: =IF(D10="Order",A10,"") -> Label Sticker Roll 30mm x 40mm（Local） | U9: =IF(G10="Order",A10,"") -> Label Sticker Roll 30mm x 40mm（Local） | V9: =IF(J10="Order",A10,"") -> Label Sticker Roll 30mm x 40mm（Local） | W9: =IF(M10="Order",A10,"") -> Label Sticker Roll 30mm x 40mm（Local） | X9: =IF(P10="Order",A10,"") -> Label Sticker Roll 30mm x 40mm（Local）
A10: Label Sticker Roll 30mm x 40mm（Local） | B10: 0 | C10: Roll | D10: =IF(B10<=$Q10,"Order","") -> Order | F10: Roll | G10: =IF(E10<=$Q10,"Order","") -> Order | I10: Roll | J10: =IF(H10<=$Q10,"Order","") -> Order | L10: Roll | M10: =IF(K10<=$Q10,"Order","") -> Order | O10: Roll | P10: =IF(N10<=$Q10,"Order","") -> Order | Q10: 10 | T10: =IF(D12="Order",A12,"") -> Delivery Thank You Note | U10: =IF(G12="Order",A12,"") -> Delivery Thank You Note | V10: =IF(J12="Order",A12,"") -> Delivery Thank You Note | W10: =IF(M12="Order",A12,"") -> Delivery Thank You Note | X10: =IF(P12="Order",A12,"") -> Delivery Thank You Note
A11: Label Sticker Roll 30mm x 40mm（China） | B11: 13 | C11: Roll | D11: =IF(B11<=$Q11,"Order","") | F11: Roll | G11: =IF(E11<=$Q11,"Order","") -> Order | I11: Roll | J11: =IF(H11<=$Q11,"Order","") -> Order | L11: Roll | M11: =IF(K11<=$Q11,"Order","") -> Order | O11: Roll | P11: =IF(N11<=$Q11,"Order","") -> Order | Q11: 10 | T11: =IF(D13="Order",A13,"") | U11: =IF(G13="Order",A13,"") -> Delivery Location Note | V11: =IF(J13="Order",A13,"") -> Delivery Location Note | W11: =IF(M13="Order",A13,"") -> Delivery Location Note | X11: =IF(P13="Order",A13,"") -> Delivery Location Note
A12: Delivery Thank You Note | B12: 5 | C12: Bundle | D12: =IF(B12<=$Q12,"Order","") -> Order | F12: Bundle | G12: =IF(E12<=$Q12,"Order","") -> Order | I12: Bundle | J12: =IF(H12<=$Q12,"Order","") -> Order | L12: Bundle | M12: =IF(K12<=$Q12,"Order","") -> Order | O12: Bundle | P12: =IF(N12<=$Q12,"Order","") -> Order | Q12: 5 | T12: =IF(D13="Order",A13,"") | U12: =IF(G13="Order",A13,"") -> Delivery Location Note | V12: =IF(J13="Order",A13,"") -> Delivery Location Note | W12: =IF(M13="Order",A13,"") -> Delivery Location Note | X12: =IF(P13="Order",A13,"") -> Delivery Location Note
A13: Delivery Location Note | B13: 3 | C13: Bundle | D13: =IF(B13<=$Q13,"Order","") | F13: Bundle | G13: =IF(E13<=$Q13,"Order","") -> Order | I13: Bundle | J13: =IF(H13<=$Q13,"Order","") -> Order | L13: Bundle | M13: =IF(K13<=$Q13,"Order","") -> Order | O13: Bundle | P13: =IF(N13<=$Q13,"Order","") -> Order | Q13: 1 | T13: =IF(D14="Order",A14,"") | U13: =IF(G14="Order",A14,"") -> Mop Detergent (BIO PINE / Apple Floor) | V13: =IF(J14="Order",A14,"") -> Mop Detergent (BIO PINE / Apple Floor) | W13: =IF(M14="Order",A14,"") -> Mop Detergent (BIO PINE / Apple Floor) | X13: =IF(P14="Order",A14,"") -> Mop Detergent (BIO PINE / Apple Floor)
A14: Mop Detergent (BIO PINE / Apple Floor) | B14: 1.6 | C14: Bottle | D14: =IF(B14<=$Q14,"Order","") | F14: Bottle | G14: =IF(E14<=$Q14,"Order","") -> Order | I14: Bottle | J14: =IF(H14<=$Q14,"Order","") -> Order | L14: Bottle | M14: =IF(K14<=$Q14,"Order","") -> Order | O14: Bottle | P14: =IF(N14<=$Q14,"Order","") -> Order | Q14: 1 | T14: =IF(D15="Order",A15,"") | U14: =IF(G15="Order",A15,"") -> Washing Detergent (Extra Power Full 10 LITER) | V14: =IF(J15="Order",A15,"") -> Washing Detergent (Extra Power Full 10 LITER) | W14: =IF(M15="Order",A15,"") -> Washing Detergent (Extra Power Full 10 LITER) | X14: =IF(P15="Order",A15,"") -> Washing Detergent (Extra Power Full 10 LITER)
A15: Washing Detergent (Extra Power Full 10 LITER) | B15: 1.3 | C15: Bottle | D15: =IF(B15<=$Q15,"Order","") | F15: Bottle | G15: =IF(E15<=$Q15,"Order","") -> Order | I15: Bottle | J15: =IF(H15<=$Q15,"Order","") -> Order | L15: Bottle | M15: =IF(K15<=$Q15,"Order","") -> Order | O15: Bottle | P15: =IF(N15<=$Q15,"Order","") -> Order | Q15: 1 | T15: =IF(D16="Order",A16,"") -> Cloth Detergent (Top) | U15: =IF(G16="Order",A16,"") -> Cloth Detergent (Top) | V15: =IF(J16="Order",A16,"") -> Cloth Detergent (Top) | W15: =IF(M16="Order",A16,"") -> Cloth Detergent (Top) | X15: =IF(P16="Order",A16,"") -> Cloth Detergent (Top)
A16: Cloth Detergent (Top) | B16: 0.2 | C16: Pack | D16: =IF(B16<=$Q16,"Order","") -> Order | F16: Pack | G16: =IF(E16<=$Q16,"Order","") -> Order | I16: Pack | J16: =IF(H16<=$Q16,"Order","") -> Order | L16: Pack | M16: =IF(K16<=$Q16,"Order","") -> Order | O16: Pack | P16: =IF(N16<=$Q16,"Order","") -> Order | Q16: 0.5 | T16: =IF(D17="Order",A17,"") | U16: =IF(G17="Order",A17,"") -> Hand Detergent | V16: =IF(J17="Order",A17,"") -> Hand Detergent | W16: =IF(M17="Order",A17,"") -> Hand Detergent | X16: =IF(P17="Order",A17,"") -> Hand Detergent
A17: Hand Detergent | B17: 3.7 | C17: Bottle | D17: =IF(B17<=$Q17,"Order","") | F17: Bottle | G17: =IF(E17<=$Q17,"Order","") -> Order | I17: Bottle | J17: =IF(H17<=$Q17,"Order","") -> Order | L17: Bottle | M17: =IF(K17<=$Q17,"Order","") -> Order | O17: Bottle | P17: =IF(N17<=$Q17,"Order","") -> Order | Q17: 1 | T17: =IF(D18="Order",A18,"") | U17: =IF(G18="Order",A18,"") -> Harpic Toilet Cleaner | V17: =IF(J18="Order",A18,"") -> Harpic Toilet Cleaner | W17: =IF(M18="Order",A18,"") -> Harpic Toilet Cleaner | X17: =IF(P18="Order",A18,"") -> Harpic Toilet Cleaner
A18: Harpic Toilet Cleaner | B18: 1.5 | C18: Bottle | D18: =IF(B18<=$Q18,"Order","") | F18: Bottle | G18: =IF(E18<=$Q18,"Order","") -> Order | I18: Bottle | J18: =IF(H18<=$Q18,"Order","") -> Order | L18: Bottle | M18: =IF(K18<=$Q18,"Order","") -> Order | O18: Bottle | P18: =IF(N18<=$Q18,"Order","") -> Order | Q18: 1 | T18: =IF(D19="Order",A19,"") -> Degrease Foam Detergent | U18: =IF(G19="Order",A19,"") -> Degrease Foam Detergent | V18: =IF(J19="Order",A19,"") -> Degrease Foam Detergent | W18: =IF(M19="Order",A19,"") -> Degrease Foam Detergent | X18: =IF(P19="Order",A19,"") -> Degrease Foam Detergent
A19: Degrease Foam Detergent | B19: 0.4 | C19: Bottle | D19: =IF(B19<=$Q19,"Order","") -> Order | F19: Bottle | G19: =IF(E19<=$Q19,"Order","") -> Order | I19: Bottle | J19: =IF(H19<=$Q19,"Order","") -> Order | L19: Bottle | M19: =IF(K19<=$Q19,"Order","") -> Order | O19: Bottle | P19: =IF(N19<=$Q19,"Order","") -> Order | Q19: 0.5 | T19: =IF(D20="Order",A20,"") | U19: =IF(G20="Order",A20,"") -> Sponge (Yellow - pcs) | V19: =IF(J20="Order",A20,"") -> Sponge (Yellow - pcs) | W19: =IF(M20="Order",A20,"") -> Sponge (Yellow - pcs) | X19: =IF(P20="Order",A20,"") -> Sponge (Yellow - pcs)
A20: Sponge (Yellow - pcs) | B20: 5 | C20: Pcs | D20: =IF(B20<=$Q20,"Order","") | F20: Pcs | G20: =IF(E20<=$Q20,"Order","") -> Order | I20: Pcs | J20: =IF(H20<=$Q20,"Order","") -> Order | L20: Pcs | M20: =IF(K20<=$Q20,"Order","") -> Order | O20: Pcs | P20: =IF(N20<=$Q20,"Order","") -> Order | Q20: 1 | T20: =IF(D21="Order",A21,"") | U20: =IF(G21="Order",A21,"") -> Scrub Pad (Green - pcs) | V20: =IF(J21="Order",A21,"") -> Scrub Pad (Green - pcs) | W20: =IF(M21="Order",A21,"") -> Scrub Pad (Green - pcs) | X20: =IF(P21="Order",A21,"") -> Scrub Pad (Green - pcs)
A21: Scrub Pad (Green - pcs) | B21: 3 | C21: Pcs | D21: =IF(B21<=$Q21,"Order","") | F21: Pcs | G21: =IF(E21<=$Q21,"Order","") -> Order | I21: Pcs | J21: =IF(H21<=$Q21,"Order","") -> Order | L21: Pcs | M21: =IF(K21<=$Q21,"Order","") -> Order | O21: Pcs | P21: =IF(N21<=$Q21,"Order","") -> Order | Q21: 1 | T21: =IF(D22="Order",A22,"") -> Tissue Roll (Toilet) | U21: =IF(G22="Order",A22,"") -> Tissue Roll (Toilet) | V21: =IF(J22="Order",A22,"") -> Tissue Roll (Toilet) | W21: =IF(M22="Order",A22,"") -> Tissue Roll (Toilet) | X21: =IF(P22="Order",A22,"") -> Tissue Roll (Toilet)
A22: Tissue Roll (Toilet) | B22: 5 | C22: Roll | D22: =IF(B22<=$Q22,"Order","") -> Order | F22: Roll | G22: =IF(E22<=$Q22,"Order","") -> Order | I22: Roll | J22: =IF(H22<=$Q22,"Order","") -> Order | L22: Roll | M22: =IF(K22<=$Q22,"Order","") -> Order | O22: Roll | P22: =IF(N22<=$Q22,"Order","") -> Order | Q22: 6 | T22: =IF(D23="Order",A23,"") -> Kitchen Towel | U22: =IF(G23="Order",A23,"") -> Kitchen Towel | V22: =IF(J23="Order",A23,"") -> Kitchen Towel | W22: =IF(M23="Order",A23,"") -> Kitchen Towel | X22: =IF(P23="Order",A23,"") -> Kitchen Towel
A23: Kitchen Towel | B23: 3 | C23: Roll | D23: =IF(B23<=$Q23,"Order","") -> Order | F23: Roll | G23: =IF(E23<=$Q23,"Order","") -> Order | I23: Roll | J23: =IF(H23<=$Q23,"Order","") -> Order | L23: Roll | M23: =IF(K23<=$Q23,"Order","") -> Order | O23: Roll | P23: =IF(N23<=$Q23,"Order","") -> Order | Q23: 3 | T23: =IF(D24="Order",A24,"") | U23: =IF(G24="Order",A24,"") -> Tissue Box Tissue Refill pack ( Half Cut ) | V23: =IF(J24="Order",A24,"") -> Tissue Box Tissue Refill pack ( Half Cut ) | W23: =IF(M24="Order",A24,"") -> Tissue Box Tissue Refill pack ( Half Cut ) | X23: =IF(P24="Order",A24,"") -> Tissue Box Tissue Refill pack ( Half Cut )
... A35: Disposable Glove (Pack) | B35: 14 | C35: Pack | D35: =IF(B35<=$Q35,"Order","") | F35: Pack | G35: =IF(E35<=$Q35,"Order","") -> Order | I35: Pack | J35: =IF(H35<=$Q35,"Order","") -> Order | L35: Pack | M35: =IF(K35<=$Q35,"Order","") -> Order | O35: Pack | P35: =IF(N35<=$Q35,"Order","") -> Order | Q35: 12 | T35: =IF(D36="Order",A36,"") | U35: =IF(G36="Order",A36,"") | V35: =IF(J36="Order",A36,"") | W35: =IF(M36="Order",A36,"") | X35: =IF(P36="Order",A36,"")
A36: Disposable Glove (Pack- TaPau Trading) | B36: 1 | C36: Pack | D36: =IF(B36<=4,"Spare Item","") -> Spare Item | F36: Pack | G36: =IF(E36<=4,"Spare Item","") -> Spare Item | I36: Pack | J36: =IF(H36<=4,"Spare Item","") -> Spare Item | L36: Pack | M36: =IF(K36<=4,"Spare Item","") -> Spare Item | O36: Pack | P36: =IF(N36<=4,"Spare Item","") -> Spare Item | Q36: 4 | T36: =IF(D37="Order",A37,"") | U36: =IF(G37="Order",A37,"") -> Freshmatic automatic spray cartridge | V36: =IF(J37="Order",A37,"") -> Freshmatic automatic spray cartridge | W36: =IF(M37="Order",A37,"") -> Freshmatic automatic spray cartridge | X36: =IF(P37="Order",A37,"") -> Freshmatic automatic spray cartridge
A37: Freshmatic automatic spray cartridge | B37: 3 | C37: Pcs | D37: =IF(B37<=$Q37,"Order","") | F37: Pcs | G37: =IF(E37<=$Q37,"Order","") -> Order | I37: Pcs | J37: =IF(H37<=$Q37,"Order","") -> Order | L37: Pcs | M37: =IF(K37<=$Q37,"Order","") -> Order | O37: Pcs | P37: =IF(N37<=$Q37,"Order","") -> Order | Q37: 0 | T37: =IF(D38="Order",A38,"") | U37: =IF(G38="Order",A38,"") -> Toilet refresher | V37: =IF(J38="Order",A38,"") -> Toilet refresher | W37: =IF(M38="Order",A38,"") -> Toilet refresher | X37: =IF(P38="Order",A38,"") -> Toilet refresher
A38: Toilet refresher | B38: 4 | C38: Pcs | D38: =IF(B38<=$Q38,"Order","") | F38: Pcs | G38: =IF(E38<=$Q38,"Order","") -> Order | I38: Pcs | J38: =IF(H38<=$Q38,"Order","") -> Order | L38: Pcs | M38: =IF(K38<=$Q38,"Order","") -> Order | O38: Pcs | P38: =IF(N38<=$Q38,"Order","") -> Order | Q38: 0 | T38: =IF(D39="Order",A39,"") | U38: =IF(G39="Order",A39,"") | V38: =IF(I39="Order",A39,"") | W38: =IF(L39="Order",A39,"") | X38: =IF(O39="Order",A39,"")
A46: =IF(B2="","",TEXTJOIN(" , ",TRUE,T3:T38)) -> #NAME?
A48: =IF(H2="","",TEXTJOIN(" , ",TRUE,V3:V38))
A49: =IF(K2="","",TEXTJOIN(" , ",TRUE,W3:W39))
A50: =IF(N2="","",TEXTJOIN(" , ",TRUE,X3:X38))

Sheet Stationary 
A1: Stationary Intensity listing 2026 (MONTHLY STOCK)
A2: ITEM
B3: Quantity ＆ Unit | D3: Status | E3: Min Order | F3: =IF(D4="Order",A4,"") -> Ball pen ( Blue 0.5mm/ 0.7mm)
A4: Ball pen ( Blue 0.5mm/ 0.7mm) | C4: PCS | D4: =IF(B4<=$E4,"Order","") -> Order | E4: 1 | F4: =IF(D5="Order",A5,"") -> Ball pen ( Black 0.5mm/ 0.7mm)
A5: Ball pen ( Black 0.5mm/ 0.7mm) | C5: PCS | D5: =IF(B5<=$E5,"Order","") -> Order | E5: 1 | F5: =IF(D6="Order",A6,"") -> Marker pen ( Blue )
A6: Marker pen ( Blue ) | C6: PCS | D6: =IF(B6<=$E6,"Order","") -> Order | E6: 1 | F6: =IF(D7="Order",A7,"") -> Marker pen (Black)
A7: Marker pen (Black) | C7: PCS | D7: =IF(B7<=$E7,"Order","") -> Order | E7: 1 | F7: =IF(D8="Order",A8,"") -> White board marker ( any colour )
A8: White board marker ( any colour ) | C8: PCS | D8: =IF(B8<=$E8,"Order","") -> Order | E8: 1 | F8: =IF(D9="Order",A9,"") -> Highlighter ( any colour )
A9: Highlighter ( any colour ) | C9: PCS | D9: =IF(B9<=$E9,"Order","") -> Order | E9: 1 | F9: =IF(D10="Order",A10,"") -> Staples ( Length 5mm 1000 staples)
A10: Staples ( Length 5mm 1000 staples) | C10: BOX | D10: =IF(B10<=$E10,"Order","") -> Order | E10: 1 | F10: =IF(D11="Order",A11,"") -> Paper clips (100 pcs art. NOTR 031)
A11: Paper clips (100 pcs art. NOTR 031) | C11: BOX | D11: =IF(B11<=$E11,"Order","") -> Order | E11: 1 | F11: =IF(D12="Order",A12,"") -> Blinder clips ( DL6052 Black)
A12: Blinder clips ( DL6052 Black) | C12: BOX | D12: =IF(B12<=$E12,"Order","") -> Order | E12: 1 | F12: =IF(D13="Order",A13,"") -> Solotape ( visible )
A13: Solotape ( visible ) | C13: ROLL | D13: =IF(B13<=$E13,"Order","") -> Order | E13: 1 | F13: =IF(D14="Order",A14,"") -> Double tape
A14: Double tape | C14: ROLL | D14: =IF(B14<=$E14,"Order","") -> Order | E14: 1 | F14: =IF(D15="Order",A15,"") -> Cloth duct tape ( any colour )
A15: Cloth duct tape ( any colour ) | C15: ROLL | D15: =IF(B15<=$E15,"Order","") -> Order | E15: 1 | F15: =IF(D16="Order",A16,"") -> AA Battery
... A22: Track light replacement bulb ( 6500k) | C22: PCS | D22: =IF(B22<=$E22,"Order","") -> Order | E22: 1 | F22: =IF(D23="Order",A23,"")
A44: =IF(B2="","",TEXTJOIN(" , ",TRUE,F4:F22))
